<robot name="Poppy_Humanoid">
	<link name="pelvis">
		<inertial>
			<origin xyz="-0.000134932459328483 -0.000399086261064929 0.00195556930608449" rpy="0 0 0"></origin>
			<mass value="0.18520035953947"></mass>
			<inertia ixx="0.000101804322229161" ixy="3.56589402562651E-08" ixz="-1.38613151054156E-05" iyy="0.000142404075398435" iyz="-3.50682832702007E-06" izz="9.38193247222871E-05"></inertia>
		</inertial>
		<visual>
			<origin xyz="0 0 0" rpy="0 0 0"></origin>
			<geometry>
				<mesh filename="package://meshes/pelvis_visual.STL"></mesh>
			</geometry>
			<material name="">
				<color rgba="0.9 0.9 0.9 1.0"></color>
			</material>
		</visual>
		<collision>
			<origin xyz="0 0 0" rpy="0 0 0"></origin>
			<geometry>
				<mesh filename="package://meshes/pelvis_respondable.STL"></mesh>
			</geometry>
		</collision>
		<mass>0.18508</mass>
	</link>
	<joint name="abs_y" type="revolute">
		<origin xyz="0 -0.017 0.061" rpy="1.5707963267949 0 0"></origin>
		<parent link="pelvis"></parent>
		<child link="abs_motors"></child>
		<axis xyz="-1 0 0"></axis>
		<limit effort="7.3" lower="-0.872664625997" upper="0.209439510239" velocity="8.2"></limit>
	</joint>
	<link name="abs_motors">
		<inertial>
			<origin xyz="-6.29779489192246E-05 0.0133591399673186 -0.0195687625589375" rpy="0 0 0"></origin>
			<mass value="0.16766708386429"></mass>
			<inertia ixx="0.000151720676825684" ixy="-2.41666285846992E-07" ixz="-2.06688911297549E-07" iyy="0.000131382009077746" iyz="-2.13904639264389E-06" izz="6.52732386194484E-05"></inertia>
		</inertial>
		<visual>
			<origin xyz="0 0 0" rpy="0 0 0"></origin>
			<geometry>
				<mesh filename="package://meshes/abs_motors_visual.STL"></mesh>
			</geometry>
			<material name="">
				<color rgba="0.9 0.9 0.9 1.0"></color>
			</material>
		</visual>
		<collision>
			<origin xyz="0 0 0" rpy="0 0 0"></origin>
			<geometry>
				<mesh filename="package://meshes/abs_motors_respondable.STL"></mesh>
			</geometry>
		</collision>
		<mass>0.27838</mass>
	</link>
	<joint name="abs_x" type="revolute">
		<origin xyz="0 0 0" rpy="0 0 0"></origin>
		<parent link="abs_motors"></parent>
		<child link="abdomen"></child>
		<axis xyz="0 0 1"></axis>
		<limit effort="7.3" lower="-0.785398163397" upper="0.785398163397" velocity="8.2"></limit>
	</joint>
	<link name="abdomen">
		<inertial>
			<origin xyz="4.70358640929572E-07 0.0445314260459549 -0.022296044885406" rpy="0 0 0"></origin>
			<mass value="0.0384110457457536"></mass>
			<inertia ixx="5.9365236572053E-05" ixy="-8.257716306361E-11" ixz="-2.55036869156096E-10" iyy="5.98640694082658E-05" iyz="3.94818292640265E-07" izz="2.35987614893539E-05"></inertia>
		</inertial>
		<visual>
			<origin xyz="0 0 0" rpy="0 0 0"></origin>
			<geometry>
				<mesh filename="package://meshes/abdomen_visual.STL"></mesh>
			</geometry>
			<material name="">
				<color rgba="0.9 0.9 0.9 1.0"></color>
			</material>
		</visual>
		<collision>
			<origin xyz="0 0 0" rpy="0 0 0"></origin>
			<geometry>
				<mesh filename="package://meshes/abdomen_respondable.STL"></mesh>
			</geometry>
		</collision>
		<mass>0.03839</mass>
	</link>
	<joint name="abs_z" type="revolute">
		<origin xyz="0 0.0516374742048976 0" rpy="0 0 0"></origin>
		<parent link="abdomen"></parent>
		<child link="spine"></child>
		<axis xyz="0 1 0"></axis>
		<limit effort="3.1" lower="-1.57079632679" upper="1.57079632679" velocity="7.0"></limit>
	</joint>
	<link name="spine">
		<inertial>
			<origin xyz="-2.40411891850495E-07 0.0288451667347867 -0.0100975118547382" rpy="0 0 0"></origin>
			<mass value="0.0926815106655512"></mass>
			<inertia ixx="3.84763910015325E-05" ixy="-1.20593001730888E-09" ixz="-2.38589260905183E-10" iyy="2.7320514654861E-05" iyz="1.47490149318973E-06" izz="3.26595211965373E-05"></inertia>
		</inertial>
		<visual>
			<origin xyz="0 0 0" rpy="0 0 0"></origin>
			<geometry>
				<mesh filename="package://meshes/spine_visual.STL"></mesh>
			</geometry>
			<material name="">
				<color rgba="0.9 0.9 0.9 1.0"></color>
			</material>
		</visual>
		<collision>
			<origin xyz="0 0 0" rpy="0 0 0"></origin>
			<geometry>
				<mesh filename="package://meshes/spine_respondable.STL"></mesh>
			</geometry>
		</collision>
		<mass>0.09264</mass>
	</link>
	<joint name="bust_y" type="revolute">
		<origin xyz="0 0.07985 0.00279999999999998" rpy="0 0 0"></origin>
		<parent link="spine"></parent>
		<child link="bust_motors"></child>
		<axis xyz="-1 0 0"></axis>
		<limit effort="3.1" lower="-1.16937059884" upper="0.471238898038" velocity="7.0"></limit>
	</joint>
	<link name="bust_motors">
		<inertial>
			<origin xyz="3.50872416629779E-05 0.0105220286877652 -0.0174331453843439" rpy="0 0 0"></origin>
			<mass value="0.158876054570625"></mass>
			<inertia ixx="0.000100953683249293" ixy="-3.89105307189684E-07" ixz="9.71749941401585E-08" iyy="8.94288410563621E-05" iyz="-1.31738255727689E-06" izz="4.26225972692235E-05"></inertia>
		</inertial>
		<visual>
			<origin xyz="0 0 0" rpy="0 0 0"></origin>
			<geometry>
				<mesh filename="package://meshes/bust_motors_visual.STL"></mesh>
			</geometry>
			<material name="">
				<color rgba="0.9 0.9 0.9 1.0"></color>
			</material>
		</visual>
		<collision>
			<origin xyz="0 0 0" rpy="0 0 0"></origin>
			<geometry>
				<mesh filename="package://meshes/bust_motors_respondable.STL"></mesh>
			</geometry>
		</collision>
		<mass>0.15889</mass>
	</link>
	<joint name="bust_x" type="revolute">
		<origin xyz="0 0 0" rpy="0 0 0"></origin>
		<parent link="bust_motors"></parent>
		<child link="chest"></child>
		<axis xyz="0 0 1"></axis>
		<limit effort="3.1" lower="-0.698131700798" upper="0.698131700798" velocity="7.0"></limit>
	</joint>
	<link name="chest">
		<inertial>
			<origin xyz="2.35256459143538E-06 0.0514948183080913 -0.0105463056982622" rpy="0 0 0"></origin>
			<mass value="0.262925523172723"></mass>
			<inertia ixx="0.000154597294293882" ixy="2.32304239504647E-08" ixz="-2.47140128362103E-08" iyy="0.000750952782458072" iyz="1.53530143139102E-06" izz="0.000688549998744818"></inertia>
		</inertial>
		<visual>
			<origin xyz="0 0 0" rpy="0 0 0"></origin>
			<geometry>
				<mesh filename="package://meshes/chest_visual.STL"></mesh>
			</geometry>
			<material name="">
				<color rgba="0.9 0.9 0.9 1.0"></color>
			</material>
		</visual>
		<collision>
			<origin xyz="0 0 0" rpy="0 0 0"></origin>
			<geometry>
				<mesh filename="package://meshes/chest_respondable.STL"></mesh>
			</geometry>
		</collision>
		<mass>0.27528</mass>
	</link>
	<joint name="l_shoulder_y" type="revolute">
		<origin xyz="0.0771000000000001 0.0499999999999999 0.00399999999999997" rpy="-1.5707963267949 0 0"></origin>
		<parent link="chest"></parent>
		<child link="l_shoulder"></child>
		<axis xyz="1 0 0"></axis>
		<limit effort="3.1" lower="-2.09439510239" upper="2.70526034059" velocity="7.0"></limit>
	</joint>
	<link name="l_shoulder">
		<inertial>
			<origin xyz="0.0105246491971973 0.00179805316216127 -0.00915201992957032" rpy="0 0 0"></origin>
			<mass value="0.00843598968780806"></mass>
			<inertia ixx="3.39606863056539E-06" ixy="-4.79545875245114E-08" ixz="2.95435354929514E-08" iyy="3.56726082486902E-06" iyz="1.00382310579659E-08" izz="1.84634806401887E-06"></inertia>
		</inertial>
		<visual>
			<origin xyz="0 0 0" rpy="0 0 0"></origin>
			<geometry>
				<mesh filename="package://meshes/l_shoulder_visual.STL"></mesh>
			</geometry>
			<material name="">
				<color rgba="0.9 0.9 0.9 1.0"></color>
			</material>
		</visual>
		<collision>
			<origin xyz="0 0 0" rpy="0 0 0"></origin>
			<geometry>
				<mesh filename="package://meshes/l_shoulder_respondable.STL"></mesh>
			</geometry>
		</collision>
		<mass>0.00838</mass>
	</link>
	<joint name="l_shoulder_x" type="revolute">
		<origin xyz="0.0284 0 0" rpy="3.14159265358979 0 1.5707963267949"></origin>
		<parent link="l_shoulder"></parent>
		<child link="l_shoulder_motor"></child>
		<axis xyz="0 0 1"></axis>
		<limit effort="3.1" lower="-1.83259571459" upper="1.91986217719" velocity="7.0"></limit>
	</joint>
	<link name="l_shoulder_motor">
		<inertial>
			<origin xyz="2.25562237481797E-07 0.0125756739553211 0.00859826040204853" rpy="0 0 0"></origin>
			<mass value="0.0828144098443214"></mass>
			<inertia ixx="2.76486208811411E-05" ixy="1.32207552337974E-10" ixz="6.6889770978984E-10" iyy="1.64427853426986E-05" iyz="7.23401723852699E-07" izz="2.26416351010788E-05"></inertia>
		</inertial>
		<visual>
			<origin xyz="0 0 0" rpy="0 0 0"></origin>
			<geometry>
				<mesh filename="package://meshes/l_shoulder_motor_visual.STL"></mesh>
			</geometry>
			<material name="">
				<color rgba="0.9 0.9 0.9 1.0"></color>
			</material>
		</visual>
		<collision>
			<origin xyz="0 0 0" rpy="0 0 0"></origin>
			<geometry>
				<mesh filename="package://meshes/l_shoulder_motor_respondable.STL"></mesh>
			</geometry>
		</collision>
		<mass>0.08288</mass>
	</link>
</robot>